<robot name="armbot">
  <material name="black">
    <color rgba="0 0 0 1" />
  </material>
  <material name="brown">
    <color rgba="0.82 0.31 0.12 1" />
  </material>

  <link name="base_turn_table_basement">
    <visual>
      <origin rpy="0 0 0" xyz="0 0 0.031" />
      <material name="brown" />
      <geometry>
        <mesh filename="package://armbot_description/meshes/base_turn_table_basement.stl" />
      </geometry>
    </visual>
  </link>

  <link name="base_turn_table_top">
    <visual>
      <origin rpy="0 0 0" xyz="0 0 0" />
      <material name="brown" />
      <geometry>
        <mesh filename="package://armbot_description/meshes/base_turn_table_top.stl" />
      </geometry>
    </visual>
  </link>

  <link name="base_turn_table">
    <visual>
      <origin rpy="0 0 0" xyz="0 0 0" />
      <material name="brown" />
      <geometry>
        <mesh filename="package://armbot_description/meshes/base_turn_table_upd.stl" />
      </geometry>
    </visual>
  </link>

  <link name="arm1">
    <visual>
      <origin rpy="-1.570796327 -1.570796327 3.1415926535" xyz="-0.047 0 0" />
      <material name="brown" />
      <geometry>
        <mesh filename="package://armbot_description/meshes/arm.stl" />
      </geometry>
    </visual>
  </link>

  <link name="arm2">
    <visual>
      <origin rpy="-1.570796327 -1.570796327 3.1415926535" xyz="-0.047 0 0" />
      <material name="brown" />
      <geometry>
        <mesh filename="package://armbot_description/meshes/arm.stl" />
      </geometry>
    </visual>
  </link>

  <link name="wrist">
    <visual>
      <origin rpy="3.1415926535 1.570796327 0" xyz="-0.017 -0.013 -0.005" />
      <material name="brown" />
      <geometry>
        <mesh filename="package://armbot_description/meshes/wrist_mirror.stl" />
      </geometry>
    </visual>
  </link>

  <link name="wrist_rotate">
    <visual>
      <origin rpy="3.1415926535 3.1415926535 1.570796327" xyz="0.01 0 0.0275" />
      <material name="brown" />
      <geometry>
        <mesh filename="package://armbot_description/meshes/wrist_rotate.stl" />
      </geometry>
    </visual>
  </link>


  <link name="motor1">
    <visual>
      <origin rpy="0 0 0" xyz="0 0 0" />
      <material name="black" />
      <geometry>
        <mesh filename="package://armbot_description/meshes/dynamixel_upd.stl" />
      </geometry>
    </visual>
  </link>

  <link name="motor2">
    <visual>
      <origin rpy="3.1415926535 0 0" xyz="0 0 0" />
      <material name="black" />
      <geometry>
        <mesh filename="package://armbot_description/meshes/dynamixel_upd.stl" />
      </geometry>
    </visual>
  </link>

  <link name="motor3">
    <visual>
      <origin rpy="3.1415926535 0 0" xyz="0 0 0" />
      <material name="black" />
      <geometry>
        <mesh filename="package://armbot_description/meshes/dynamixel_upd.stl" />
      </geometry>
    </visual>
  </link>

  <link name="motor4">
    <visual>
      <origin rpy="3.1415926535 0 0" xyz="0 0 0" />
      <material name="black" />
      <geometry>
        <mesh filename="package://armbot_description/meshes/dynamixel_upd.stl" />
      </geometry>
    </visual>
  </link>

  <link name="motor5">
    <visual>
      <origin rpy="0 0 0" xyz="0 0 0" />
      <material name="black" />
      <geometry>
        <mesh filename="package://armbot_description/meshes/dynamixel_upd.stl" />
      </geometry>
    </visual>
  </link>

  <link name="motor6">
    <visual>
      <origin rpy="0 0 0" xyz="0 0 0" />
      <material name="black" />
      <geometry>
        <mesh filename="package://armbot_description/meshes/dynamixel_upd.stl" />
      </geometry>
    </visual>
  </link>

  <joint name="basement_to_base_top" type="fixed">
    <parent link="base_turn_table_basement" />
    <child link="base_turn_table_top" />
    <origin rpy="0 0 0" xyz="0 -0.0077 0.083" />
  </joint>

  <joint name="base_top_to_motor1" type="fixed">
    <parent link="base_turn_table_top" />
    <child link="motor1" />
    <origin rpy="0 0 -1.570796327" xyz="0 0.015 -0.016" />
  </joint>

  <joint name="motor1_to_base_turn_table" type="continuous">
    <parent link="motor1" />
    <child link="base_turn_table" />
    <origin rpy="0 0 0" xyz="0 0 0.028" />
    <axis xyz="0 0 1" />
  </joint>

  <joint name="base_turn_table_to_motor2" type="fixed">
    <parent link="base_turn_table" />
    <child link="motor2" />
    <origin rpy="0 1.570796327 3.1415926535" xyz="0 0 0.038" />
  </joint>

  <joint name="motor2_to_arm1" type="continuous">
    <parent link="motor2" />
    <child link="arm1" />
    <origin rpy="0 0 0" xyz="0 0 0.003" />
    <axis xyz="0 0 1" />
  </joint>

  <joint name="arm1_to_motor3" type="fixed">
    <parent link="arm1" />
    <child link="motor3" />
    <origin rpy="0 0 0" xyz="-0.1116 0 -0.0032" />
  </joint>

  <joint name="motor3_to_arm2" type="continuous">
    <parent link="motor3" />
    <child link="arm2" />
    <origin rpy="0 0 0" xyz="0 0 0.003" />
    <axis xyz="0 0 1" />
  </joint>

  <joint name="arm2_to_motor4" type="fixed">
    <parent link="arm2" />
    <child link="motor4" />
    <origin rpy="0 0 0" xyz="-0.1116 0 -0.0032" />
  </joint>

  <joint name="motor4_to_wrist" type="continuous">
    <parent link="motor4" />
    <child link="wrist" />
    <origin rpy="0 0 0" xyz="0 0 0" />
    <axis xyz="0 0 1" />
  </joint>

  <joint name="wrist_to_motor5" type="fixed">
    <parent link="wrist" />
    <child link="motor5" />
    <origin rpy="1.570796327 0 -1.570796327" xyz="-0.045 0 -0.0015" />
  </joint>

  <joint name="motor5_to_wrist_rotate" type="continuous">
    <parent link="motor5" />
    <child link="wrist_rotate" />
    <origin rpy="0 0 0" xyz="0 0 0" />
    <axis xyz="0 0 1" />
  </joint>

  <joint name="wrist_rotate_to_motor6" type="fixed">
    <parent link="wrist_rotate" />
    <child link="motor6" />
    <origin rpy="0 0 0" xyz="0 0 0.048" />
  </joint>
</robot>
